<?xml version="1.0"?>
<robot name="differential_robot" xmlns:xacro="http://www.ros.org/wiki/xacro">

  <xacro:include filename="$(find ex0601)/urdf/ex0601.gazebo.xacro" />

  <xacro:property name="base_width" value="0.31"/>
  <xacro:property name="base_length" value="0.42"/>
  <xacro:property name="base_height" value="0.18"/>
  <xacro:property name="wheel_radius" value="0.10"/>
  <xacro:property name="wheel_width" value="0.04"/>

  <material name="blue"><color rgba="0 0 1 1"/></material>
  <material name="black"><color rgba="0 0 0 1"/></material>
  <material name="silver"><color rgba="0.75 0.75 0.75 1"/></material>

  <link name="base_footprint"/>
  <joint name="base_joint" type="fixed">
    <parent link="base_footprint"/>
    <child link="base_link"/>
    <origin xyz="0 0 0.1" rpy="0 0 0"/>
  </joint>

  <link name="base_link">
    <visual>
      <geometry><box size="${base_length} ${base_width} ${base_height}"/></geometry>
      <material name="blue"/>
    </visual>
    <collision>
      <geometry><box size="${base_length} ${base_width} ${base_height}"/></geometry>
    </collision>
    <inertial>
      <mass value="5.0"/>
      <inertia ixx="0.05" ixy="0" ixz="0" iyy="0.08" iyz="0" izz="0.1"/>
    </inertial>
  </link>

  <!-- Лидар детектит кабину как препятствие, поэтому придётся от неё избавиться -->
  <!-- <link name="cabin">
    <visual>
      <geometry><box size="0.3 0.25 0.15"/></geometry>
      <material name="silver"/>
    </visual>
  </link>
  <joint name="cabin_joint" type="fixed">
    <parent link="base_link"/>
    <child link="cabin"/>
    <origin xyz="-0.05 0 0.16" rpy="0 0 0"/>
  </joint> -->

  <link name="bumper">
    <visual>
      <geometry><box size="0.05 0.35 0.1"/></geometry>
      <material name="black"/>
    </visual>
  </link>
  <joint name="bumper_joint" type="fixed">
    <parent link="base_link"/>
    <child link="bumper"/> 
    <origin xyz="0.21 0 -0.02" rpy="0 0 0"/> 
  </joint>

  <xacro:macro name="wheel" params="prefix x_reflect y_reflect">
    <link name="drivewhl_${prefix}_link">
      <visual>
        <origin xyz="0 0 0" rpy="${pi/2} 0 0"/>
        <geometry><cylinder radius="${wheel_radius}" length="${wheel_width}"/></geometry>
        <material name="black"/>
      </visual>
      <collision>
        <origin xyz="0 0 0" rpy="${pi/2} 0 0"/>
        <geometry><cylinder radius="${wheel_radius}" length="${wheel_width}"/></geometry>
      </collision>
      <inertial>
        <mass value="0.5"/>
        <inertia ixx="0.001" ixy="0" ixz="0" iyy="0.001" iyz="0" izz="0.001"/>
      </inertial>
    </link>
    <joint name="drivewhl_${prefix}_joint" type="continuous">
      <parent link="base_link"/>
      <child link="drivewhl_${prefix}_link"/>
      <origin xyz="${x_reflect*0.12} ${y_reflect*0.18} -0.05" rpy="0 0 0"/>
      <axis xyz="0 1 0"/>
    </joint>
  </xacro:macro>

  <xacro:wheel prefix="fl" x_reflect="1" y_reflect="1" />
  <xacro:wheel prefix="fr" x_reflect="1" y_reflect="-1" />
  <xacro:wheel prefix="rl" x_reflect="-1" y_reflect="1" />
  <xacro:wheel prefix="rr" x_reflect="-1" y_reflect="-1" />

  <link name="lidar">
    <visual>
      <origin xyz="0 0 0" rpy="0 0 0"/>
      <geometry>
        <cylinder radius="0.05" length="0.04"/>
      </geometry>
      <material name="black"/>
    </visual>
    <inertial>
      <mass value="0.1"/>
      <inertia ixx="0.0001" ixy="0" ixz="0" iyy="0.0001" iyz="0" izz="0.0001"/>
    </inertial>
  </link>

  <joint name="lidar_joint" type="fixed">
    <parent link="base_link"/>
    <child link="lidar"/>
    <origin xyz="0.2 0 0.1" rpy="0 0 0"/>
  </joint>

  <link name="imu_link">
    <visual>
      <geometry>
        <box size="0.05 0.05 0.02"/>
      </geometry>
      <material name="black"/>
    </visual>
    <inertial>
      <mass value="0.01"/>
      <inertia ixx="1e-5" ixy="0" ixz="0" iyy="1e-5" iyz="0" izz="1e-5"/>
    </inertial>
  </link>

  <joint name="imu_joint" type="fixed">
    <parent link="base_link"/>
    <child link="imu_link"/>
    <origin xyz="0 0 0.05" rpy="0 0 0"/>
  </joint>

</robot>